INFO 2018-11-20 16:32:18,987 basehttp 124 "GET / HTTP/1.1" 200 1714
WARNING 2018-11-20 16:32:19,200 base 152 Not Found: /favicon.ico
WARNING 2018-11-20 16:32:19,201 basehttp 124 "GET /favicon.ico HTTP/1.1" 404 1967
INFO 2018-11-20 19:56:34,123 basehttp 124 "GET / HTTP/1.1" 200 1714
WARNING 2018-11-20 19:56:34,257 base 152 Not Found: /favicon.ico
WARNING 2018-11-20 19:56:34,259 basehttp 124 "GET /favicon.ico HTTP/1.1" 404 1967
INFO 2018-11-20 19:56:35,109 basehttp 124 "GET / HTTP/1.1" 200 1714
WARNING 2018-11-20 19:56:35,177 base 152 Not Found: /favicon.ico
WARNING 2018-11-20 19:56:35,179 basehttp 124 "GET /favicon.ico HTTP/1.1" 404 1967
WARNING 2018-11-20 19:56:43,809 base 152 Not Found: /categories/163/
WARNING 2018-11-20 19:56:43,809 base 152 Not Found: /categories/163/skus/
WARNING 2018-11-20 19:56:43,811 basehttp 124 "GET /categories/163/ HTTP/1.1" 404 1985
INFO 2018-11-20 19:56:43,813 basehttp 124 "OPTIONS /cart/ HTTP/1.1" 200 0
WARNING 2018-11-20 19:56:43,820 base 152 Not Found: /categories/163/hotskus/
WARNING 2018-11-20 19:56:43,821 basehttp 124 "GET /categories/163/hotskus/ HTTP/1.1" 404 2009
WARNING 2018-11-20 19:56:43,823 basehttp 124 "GET /categories/163/skus/?page=1&page_size=5&ordering=-create_time HTTP/1.1" 404 2049
INFO 2018-11-20 19:57:09,495 basehttp 124 "GET / HTTP/1.1" 200 1714
WARNING 2018-11-20 19:57:09,548 base 152 Not Found: /favicon.ico
WARNING 2018-11-20 19:57:09,552 basehttp 124 "GET /favicon.ico HTTP/1.1" 404 1967
INFO 2018-11-20 19:57:10,313 basehttp 124 "GET / HTTP/1.1" 200 1714
WARNING 2018-11-20 19:57:10,338 base 152 Not Found: /favicon.ico
WARNING 2018-11-20 19:57:10,339 basehttp 124 "GET /favicon.ico HTTP/1.1" 404 1967
WARNING 2018-11-20 20:10:53,678 base 152 Not Found: /users/
WARNING 2018-11-20 20:10:53,679 basehttp 124 "GET /users/ HTTP/1.1" 404 1952
WARNING 2018-11-20 20:10:53,775 base 152 Not Found: /favicon.ico
WARNING 2018-11-20 20:10:53,776 basehttp 124 "GET /favicon.ico HTTP/1.1" 404 1967
WARNING 2018-11-20 21:09:19,204 base 152 Not Found: /usernames/xiaoming
WARNING 2018-11-20 21:09:19,207 basehttp 124 "GET /usernames/xiaoming HTTP/1.1" 404 1988
WARNING 2018-11-20 21:09:49,487 base 152 Not Found: /usernames
WARNING 2018-11-20 21:09:49,488 basehttp 124 "GET /usernames HTTP/1.1" 404 1961
WARNING 2018-11-20 21:17:04,659 base 152 Not Found: /usernames
WARNING 2018-11-20 21:17:04,660 basehttp 124 "GET /usernames HTTP/1.1" 404 2346
WARNING 2018-11-20 21:18:46,045 base 152 Not Found: /usernames
WARNING 2018-11-20 21:18:46,046 basehttp 124 "GET /usernames HTTP/1.1" 404 2346
WARNING 2018-11-20 21:19:45,407 base 152 Not Found: /
WARNING 2018-11-20 21:19:45,408 basehttp 124 "GET /?usernames=zhangsan HTTP/1.1" 404 2320
WARNING 2018-11-20 21:20:50,598 base 152 Not Found: /usernames
WARNING 2018-11-20 21:20:50,600 basehttp 124 "GET /usernames?zhangsan HTTP/1.1" 404 2355
WARNING 2018-11-20 21:21:00,455 base 152 Not Found: /usernames/zhangsan
WARNING 2018-11-20 21:21:00,455 basehttp 124 "GET /usernames/zhangsan HTTP/1.1" 404 2373
WARNING 2018-11-20 21:21:10,031 base 152 Not Found: /usernames/user1
WARNING 2018-11-20 21:21:10,032 basehttp 124 "GET /usernames/user1 HTTP/1.1" 404 2364
WARNING 2018-11-20 21:33:15,639 base 152 Not Found: /usernames
WARNING 2018-11-20 21:33:15,640 basehttp 124 "GET /usernames?username=zhangsan HTTP/1.1" 404 2364
WARNING 2018-11-20 21:34:04,291 base 152 Not Found: /usernames
WARNING 2018-11-20 21:34:04,296 basehttp 124 "GET /usernames?username=zhangsan HTTP/1.1" 404 2364
WARNING 2018-11-20 21:34:24,272 base 152 Not Found: /usernames
WARNING 2018-11-20 21:34:24,273 basehttp 124 "GET /usernames?username=zhangsan HTTP/1.1" 404 2364
WARNING 2018-11-20 21:36:34,662 base 152 Not Found: /usernames
WARNING 2018-11-20 21:36:34,663 basehttp 124 "GET /usernames?username=zhangsan HTTP/1.1" 404 2364
WARNING 2018-11-20 21:36:37,675 base 152 Not Found: /usernames
WARNING 2018-11-20 21:36:37,675 basehttp 124 "GET /usernames HTTP/1.1" 404 2346
WARNING 2018-11-20 21:36:48,141 base 152 Not Found: /
WARNING 2018-11-20 21:36:48,141 basehttp 124 "GET / HTTP/1.1" 404 2301
WARNING 2018-11-20 21:36:54,284 base 152 Not Found: /
WARNING 2018-11-20 21:36:54,285 basehttp 124 "GET / HTTP/1.1" 404 2301
WARNING 2018-11-20 21:37:06,657 base 152 Not Found: /
WARNING 2018-11-20 21:37:06,659 basehttp 124 "GET / HTTP/1.1" 404 2301
WARNING 2018-11-20 21:37:06,822 base 152 Not Found: /favicon.ico
WARNING 2018-11-20 21:37:06,822 basehttp 124 "GET /favicon.ico HTTP/1.1" 404 2352
WARNING 2018-11-20 21:38:36,057 base 152 Not Found: /
WARNING 2018-11-20 21:38:36,058 basehttp 124 "GET / HTTP/1.1" 404 2301
WARNING 2018-11-20 21:38:36,076 base 152 Not Found: /favicon.ico
WARNING 2018-11-20 21:38:36,076 basehttp 124 "GET /favicon.ico HTTP/1.1" 404 2352
WARNING 2018-11-20 21:38:48,773 base 152 Not Found: /
WARNING 2018-11-20 21:38:48,774 basehttp 124 "GET / HTTP/1.1" 404 2301
WARNING 2018-11-20 21:38:48,838 base 152 Not Found: /favicon.ico
WARNING 2018-11-20 21:38:48,839 basehttp 124 "GET /favicon.ico HTTP/1.1" 404 2352
INFO 2018-11-20 21:39:08,896 basehttp 124 "GET /admin HTTP/1.1" 301 0
INFO 2018-11-20 21:39:08,933 basehttp 124 "GET /admin/ HTTP/1.1" 302 0
ERROR 2018-11-20 21:39:08,956 exception 135 Internal Server Error: /admin/login/
Traceback (most recent call last):
  File "/Users/zenglihui/.virtualenvs/django_py3_1.0/lib/python3.6/site-packages/django/core/handlers/exception.py", line 41, in inner
    response = get_response(request)
  File "/Users/zenglihui/.virtualenvs/django_py3_1.0/lib/python3.6/site-packages/django/core/handlers/base.py", line 187, in _get_response
    response = self.process_exception_by_middleware(e, request)
  File "/Users/zenglihui/.virtualenvs/django_py3_1.0/lib/python3.6/site-packages/django/core/handlers/base.py", line 185, in _get_response
    response = wrapped_callback(request, *callback_args, **callback_kwargs)
  File "/Users/zenglihui/.virtualenvs/django_py3_1.0/lib/python3.6/site-packages/django/views/decorators/cache.py", line 57, in _wrapped_view_func
    response = view_func(request, *args, **kwargs)
  File "/Users/zenglihui/.virtualenvs/django_py3_1.0/lib/python3.6/site-packages/django/contrib/admin/sites.py", line 377, in login
    self.each_context(request),
  File "/Users/zenglihui/.virtualenvs/django_py3_1.0/lib/python3.6/site-packages/django/contrib/admin/sites.py", line 297, in each_context
    'available_apps': self.get_app_list(request),
  File "/Users/zenglihui/.virtualenvs/django_py3_1.0/lib/python3.6/site-packages/django/contrib/admin/sites.py", line 465, in get_app_list
    app_dict = self._build_app_dict(request)
  File "/Users/zenglihui/.virtualenvs/django_py3_1.0/lib/python3.6/site-packages/django/contrib/admin/sites.py", line 413, in _build_app_dict
    has_module_perms = model_admin.has_module_permission(request)
  File "/Users/zenglihui/.virtualenvs/django_py3_1.0/lib/python3.6/site-packages/django/contrib/admin/options.py", line 482, in has_module_permission
    return request.user.has_module_perms(self.opts.app_label)
  File "/Users/zenglihui/.virtualenvs/django_py3_1.0/lib/python3.6/site-packages/django/contrib/auth/models.py", line 442, in has_module_perms
    return _user_has_module_perms(self, module)
  File "/Users/zenglihui/.virtualenvs/django_py3_1.0/lib/python3.6/site-packages/django/contrib/auth/models.py", line 201, in _user_has_module_perms
    for backend in auth.get_backends():
  File "/Users/zenglihui/.virtualenvs/django_py3_1.0/lib/python3.6/site-packages/django/contrib/auth/__init__.py", line 40, in get_backends
    return _get_backends(return_tuples=False)
  File "/Users/zenglihui/.virtualenvs/django_py3_1.0/lib/python3.6/site-packages/django/contrib/auth/__init__.py", line 29, in _get_backends
    backend = load_backend(backend_path)
  File "/Users/zenglihui/.virtualenvs/django_py3_1.0/lib/python3.6/site-packages/django/contrib/auth/__init__.py", line 23, in load_backend
    return import_string(path)()
  File "/Users/zenglihui/.virtualenvs/django_py3_1.0/lib/python3.6/site-packages/django/utils/module_loading.py", line 20, in import_string
    module = import_module(module_path)
  File "/Users/zenglihui/.virtualenvs/django_py3_1.0/lib/python3.6/importlib/__init__.py", line 126, in import_module
    return _bootstrap._gcd_import(name[level:], package, level)
  File "<frozen importlib._bootstrap>", line 994, in _gcd_import
  File "<frozen importlib._bootstrap>", line 971, in _find_and_load
  File "<frozen importlib._bootstrap>", line 953, in _find_and_load_unlocked
ModuleNotFoundError: No module named 'users.utils'
ERROR 2018-11-20 21:39:09,107 basehttp 124 "GET /admin/login/?next=/admin/ HTTP/1.1" 500 112831
WARNING 2018-11-20 21:39:09,306 base 152 Not Found: /favicon.ico
WARNING 2018-11-20 21:39:09,307 basehttp 124 "GET /favicon.ico HTTP/1.1" 404 2352
WARNING 2018-11-20 21:39:18,817 base 152 Not Found: /
WARNING 2018-11-20 21:39:18,818 basehttp 124 "GET / HTTP/1.1" 404 2301
WARNING 2018-11-20 21:39:18,900 base 152 Not Found: /favicon.ico
WARNING 2018-11-20 21:39:18,902 basehttp 124 "GET /favicon.ico HTTP/1.1" 404 2352
WARNING 2018-11-20 21:39:23,279 base 152 Not Found: /usernames
WARNING 2018-11-20 21:39:23,279 basehttp 124 "GET /usernames HTTP/1.1" 404 2346
WARNING 2018-11-20 21:39:23,363 base 152 Not Found: /favicon.ico
WARNING 2018-11-20 21:39:23,367 basehttp 124 "GET /favicon.ico HTTP/1.1" 404 2352
WARNING 2018-11-20 21:39:28,869 base 152 Not Found: /^usernames
WARNING 2018-11-20 21:39:28,870 basehttp 124 "GET /%5Eusernames HTTP/1.1" 404 2351
WARNING 2018-11-20 21:39:28,940 base 152 Not Found: /favicon.ico
WARNING 2018-11-20 21:39:28,941 basehttp 124 "GET /favicon.ico HTTP/1.1" 404 2352
WARNING 2018-11-20 21:39:35,404 base 152 Not Found: /
WARNING 2018-11-20 21:39:35,404 basehttp 124 "GET / HTTP/1.1" 404 2301
WARNING 2018-11-20 21:39:35,502 base 152 Not Found: /favicon.ico
WARNING 2018-11-20 21:39:35,504 basehttp 124 "GET /favicon.ico HTTP/1.1" 404 2352
WARNING 2018-11-20 21:39:51,333 base 152 Not Found: /usernames
WARNING 2018-11-20 21:39:51,334 basehttp 124 "GET /usernames HTTP/1.1" 404 2346
WARNING 2018-11-20 21:39:51,408 base 152 Not Found: /favicon.ico
WARNING 2018-11-20 21:39:51,409 basehttp 124 "GET /favicon.ico HTTP/1.1" 404 2352
WARNING 2018-11-20 21:42:59,209 base 152 Not Found: /usernames
WARNING 2018-11-20 21:42:59,210 basehttp 124 "GET /usernames HTTP/1.1" 404 2346
WARNING 2018-11-20 21:42:59,294 base 152 Not Found: /favicon.ico
WARNING 2018-11-20 21:42:59,296 basehttp 124 "GET /favicon.ico HTTP/1.1" 404 2352
WARNING 2018-11-20 21:43:01,663 base 152 Not Found: /
WARNING 2018-11-20 21:43:01,664 basehttp 124 "GET / HTTP/1.1" 404 2301
WARNING 2018-11-20 21:43:01,759 base 152 Not Found: /favicon.ico
WARNING 2018-11-20 21:43:01,760 basehttp 124 "GET /favicon.ico HTTP/1.1" 404 2352
WARNING 2018-11-20 21:43:03,827 base 152 Not Found: /
WARNING 2018-11-20 21:43:03,828 basehttp 124 "GET / HTTP/1.1" 404 2301
WARNING 2018-11-20 21:43:03,860 base 152 Not Found: /favicon.ico
WARNING 2018-11-20 21:43:03,861 basehttp 124 "GET /favicon.ico HTTP/1.1" 404 2352
WARNING 2018-11-20 21:43:36,477 base 152 Not Found: /
WARNING 2018-11-20 21:43:36,478 basehttp 124 "GET / HTTP/1.1" 404 2301
WARNING 2018-11-20 21:43:36,515 base 152 Not Found: /favicon.ico
WARNING 2018-11-20 21:43:36,520 basehttp 124 "GET /favicon.ico HTTP/1.1" 404 2352
WARNING 2018-11-20 21:43:50,627 base 152 Not Found: /
WARNING 2018-11-20 21:43:50,628 basehttp 124 "POST / HTTP/1.1" 404 2302
WARNING 2018-11-20 21:47:20,235 base 152 Not Found: /
WARNING 2018-11-20 21:47:20,236 basehttp 124 "POST / HTTP/1.1" 404 2301
WARNING 2018-11-20 21:47:26,781 base 152 Not Found: /usernames
WARNING 2018-11-20 21:47:26,782 basehttp 124 "POST /usernames HTTP/1.1" 404 2346
WARNING 2018-11-20 21:47:31,539 base 152 Not Found: /usernames
WARNING 2018-11-20 21:47:31,539 basehttp 124 "GET /usernames HTTP/1.1" 404 2345
WARNING 2018-11-20 21:54:55,817 base 152 Not Found: /
WARNING 2018-11-20 21:54:55,818 basehttp 124 "GET / HTTP/1.1" 404 2300
WARNING 2018-11-20 21:55:08,681 base 152 Not Found: /usernames
WARNING 2018-11-20 21:55:08,681 basehttp 124 "GET /usernames HTTP/1.1" 404 2345
WARNING 2018-11-20 21:55:25,798 base 152 Not Found: /usernames
WARNING 2018-11-20 21:55:25,799 basehttp 124 "GET /usernames HTTP/1.1" 404 2345
WARNING 2018-11-20 21:55:45,612 base 152 Not Found: /users/usernames
WARNING 2018-11-20 21:55:45,613 basehttp 124 "GET /users/usernames HTTP/1.1" 404 2363
WARNING 2018-11-20 21:55:48,545 base 152 Not Found: /usernames
WARNING 2018-11-20 21:55:48,546 basehttp 124 "GET /usernames HTTP/1.1" 404 2345
WARNING 2018-11-20 21:57:09,121 base 152 Not Found: /verifications
WARNING 2018-11-20 21:57:09,122 basehttp 124 "GET /verifications HTTP/1.1" 404 2357
WARNING 2018-11-20 21:57:41,273 base 152 Not Found: /sms_codes
WARNING 2018-11-20 21:57:41,274 basehttp 124 "GET /sms_codes HTTP/1.1" 404 2345
WARNING 2018-11-20 21:58:45,303 base 152 Not Found: /
WARNING 2018-11-20 21:58:45,305 basehttp 124 "GET / HTTP/1.1" 404 2300
WARNING 2018-11-20 22:00:54,019 base 152 Not Found: /
WARNING 2018-11-20 22:00:54,020 basehttp 124 "GET / HTTP/1.1" 404 2300
WARNING 2018-11-20 22:03:19,592 base 152 Not Found: /usernames
WARNING 2018-11-20 22:03:19,593 basehttp 124 "GET /usernames HTTP/1.1" 404 2344
WARNING 2018-11-20 22:03:33,556 base 152 Not Found: /usernames
WARNING 2018-11-20 22:03:33,557 basehttp 124 "GET /usernames HTTP/1.1" 404 2337
WARNING 2018-11-20 22:03:38,886 base 152 Not Found: /usernames
WARNING 2018-11-20 22:03:38,888 basehttp 124 "GET /usernames HTTP/1.1" 404 2338
WARNING 2018-11-20 22:04:08,841 base 152 Not Found: /usernames
WARNING 2018-11-20 22:04:08,843 basehttp 124 "GET /usernames HTTP/1.1" 404 2338
WARNING 2018-11-20 22:04:19,786 base 152 Not Found: /usernames
WARNING 2018-11-20 22:04:19,787 basehttp 124 "GET /usernames HTTP/1.1" 404 2338
INFO 2018-11-20 22:04:38,942 basehttp 124 "GET /admin HTTP/1.1" 301 0
INFO 2018-11-20 22:04:38,964 basehttp 124 "GET /admin/ HTTP/1.1" 302 0
ERROR 2018-11-20 22:04:38,971 exception 135 Internal Server Error: /admin/login/
Traceback (most recent call last):
  File "/Users/zenglihui/.virtualenvs/django_py3_1.0/lib/python3.6/site-packages/django/core/handlers/exception.py", line 41, in inner
    response = get_response(request)
  File "/Users/zenglihui/.virtualenvs/django_py3_1.0/lib/python3.6/site-packages/django/core/handlers/base.py", line 187, in _get_response
    response = self.process_exception_by_middleware(e, request)
  File "/Users/zenglihui/.virtualenvs/django_py3_1.0/lib/python3.6/site-packages/django/core/handlers/base.py", line 185, in _get_response
    response = wrapped_callback(request, *callback_args, **callback_kwargs)
  File "/Users/zenglihui/.virtualenvs/django_py3_1.0/lib/python3.6/site-packages/django/views/decorators/cache.py", line 57, in _wrapped_view_func
    response = view_func(request, *args, **kwargs)
  File "/Users/zenglihui/.virtualenvs/django_py3_1.0/lib/python3.6/site-packages/django/contrib/admin/sites.py", line 377, in login
    self.each_context(request),
  File "/Users/zenglihui/.virtualenvs/django_py3_1.0/lib/python3.6/site-packages/django/contrib/admin/sites.py", line 297, in each_context
    'available_apps': self.get_app_list(request),
  File "/Users/zenglihui/.virtualenvs/django_py3_1.0/lib/python3.6/site-packages/django/contrib/admin/sites.py", line 465, in get_app_list
    app_dict = self._build_app_dict(request)
  File "/Users/zenglihui/.virtualenvs/django_py3_1.0/lib/python3.6/site-packages/django/contrib/admin/sites.py", line 413, in _build_app_dict
    has_module_perms = model_admin.has_module_permission(request)
  File "/Users/zenglihui/.virtualenvs/django_py3_1.0/lib/python3.6/site-packages/django/contrib/admin/options.py", line 482, in has_module_permission
    return request.user.has_module_perms(self.opts.app_label)
  File "/Users/zenglihui/.virtualenvs/django_py3_1.0/lib/python3.6/site-packages/django/contrib/auth/models.py", line 442, in has_module_perms
    return _user_has_module_perms(self, module)
  File "/Users/zenglihui/.virtualenvs/django_py3_1.0/lib/python3.6/site-packages/django/contrib/auth/models.py", line 201, in _user_has_module_perms
    for backend in auth.get_backends():
  File "/Users/zenglihui/.virtualenvs/django_py3_1.0/lib/python3.6/site-packages/django/contrib/auth/__init__.py", line 40, in get_backends
    return _get_backends(return_tuples=False)
  File "/Users/zenglihui/.virtualenvs/django_py3_1.0/lib/python3.6/site-packages/django/contrib/auth/__init__.py", line 29, in _get_backends
    backend = load_backend(backend_path)
  File "/Users/zenglihui/.virtualenvs/django_py3_1.0/lib/python3.6/site-packages/django/contrib/auth/__init__.py", line 23, in load_backend
    return import_string(path)()
  File "/Users/zenglihui/.virtualenvs/django_py3_1.0/lib/python3.6/site-packages/django/utils/module_loading.py", line 20, in import_string
    module = import_module(module_path)
  File "/Users/zenglihui/.virtualenvs/django_py3_1.0/lib/python3.6/importlib/__init__.py", line 126, in import_module
    return _bootstrap._gcd_import(name[level:], package, level)
  File "<frozen importlib._bootstrap>", line 994, in _gcd_import
  File "<frozen importlib._bootstrap>", line 971, in _find_and_load
  File "<frozen importlib._bootstrap>", line 953, in _find_and_load_unlocked
ModuleNotFoundError: No module named 'users.utils'
ERROR 2018-11-20 22:04:39,063 basehttp 124 "GET /admin/login/?next=/admin/ HTTP/1.1" 500 112858
INFO 2018-11-20 22:05:12,998 basehttp 124 "GET /admin HTTP/1.1" 301 0
INFO 2018-11-20 22:05:13,017 basehttp 124 "GET /admin/ HTTP/1.1" 302 0
ERROR 2018-11-20 22:05:13,021 exception 135 Internal Server Error: /admin/login/
Traceback (most recent call last):
  File "/Users/zenglihui/.virtualenvs/django_py3_1.0/lib/python3.6/site-packages/django/core/handlers/exception.py", line 41, in inner
    response = get_response(request)
  File "/Users/zenglihui/.virtualenvs/django_py3_1.0/lib/python3.6/site-packages/django/core/handlers/base.py", line 187, in _get_response
    response = self.process_exception_by_middleware(e, request)
  File "/Users/zenglihui/.virtualenvs/django_py3_1.0/lib/python3.6/site-packages/django/core/handlers/base.py", line 185, in _get_response
    response = wrapped_callback(request, *callback_args, **callback_kwargs)
  File "/Users/zenglihui/.virtualenvs/django_py3_1.0/lib/python3.6/site-packages/django/views/decorators/cache.py", line 57, in _wrapped_view_func
    response = view_func(request, *args, **kwargs)
  File "/Users/zenglihui/.virtualenvs/django_py3_1.0/lib/python3.6/site-packages/django/contrib/admin/sites.py", line 377, in login
    self.each_context(request),
  File "/Users/zenglihui/.virtualenvs/django_py3_1.0/lib/python3.6/site-packages/django/contrib/admin/sites.py", line 297, in each_context
    'available_apps': self.get_app_list(request),
  File "/Users/zenglihui/.virtualenvs/django_py3_1.0/lib/python3.6/site-packages/django/contrib/admin/sites.py", line 465, in get_app_list
    app_dict = self._build_app_dict(request)
  File "/Users/zenglihui/.virtualenvs/django_py3_1.0/lib/python3.6/site-packages/django/contrib/admin/sites.py", line 413, in _build_app_dict
    has_module_perms = model_admin.has_module_permission(request)
  File "/Users/zenglihui/.virtualenvs/django_py3_1.0/lib/python3.6/site-packages/django/contrib/admin/options.py", line 482, in has_module_permission
    return request.user.has_module_perms(self.opts.app_label)
  File "/Users/zenglihui/.virtualenvs/django_py3_1.0/lib/python3.6/site-packages/django/contrib/auth/models.py", line 442, in has_module_perms
    return _user_has_module_perms(self, module)
  File "/Users/zenglihui/.virtualenvs/django_py3_1.0/lib/python3.6/site-packages/django/contrib/auth/models.py", line 201, in _user_has_module_perms
    for backend in auth.get_backends():
  File "/Users/zenglihui/.virtualenvs/django_py3_1.0/lib/python3.6/site-packages/django/contrib/auth/__init__.py", line 40, in get_backends
    return _get_backends(return_tuples=False)
  File "/Users/zenglihui/.virtualenvs/django_py3_1.0/lib/python3.6/site-packages/django/contrib/auth/__init__.py", line 29, in _get_backends
    backend = load_backend(backend_path)
  File "/Users/zenglihui/.virtualenvs/django_py3_1.0/lib/python3.6/site-packages/django/contrib/auth/__init__.py", line 23, in load_backend
    return import_string(path)()
  File "/Users/zenglihui/.virtualenvs/django_py3_1.0/lib/python3.6/site-packages/django/utils/module_loading.py", line 20, in import_string
    module = import_module(module_path)
  File "/Users/zenglihui/.virtualenvs/django_py3_1.0/lib/python3.6/importlib/__init__.py", line 126, in import_module
    return _bootstrap._gcd_import(name[level:], package, level)
  File "<frozen importlib._bootstrap>", line 994, in _gcd_import
  File "<frozen importlib._bootstrap>", line 971, in _find_and_load
  File "<frozen importlib._bootstrap>", line 953, in _find_and_load_unlocked
ModuleNotFoundError: No module named 'users.utils'
ERROR 2018-11-20 22:05:13,130 basehttp 124 "GET /admin/login/?next=/admin/ HTTP/1.1" 500 112858
WARNING 2018-11-20 22:05:23,431 base 152 Not Found: /usernames
WARNING 2018-11-20 22:05:23,431 basehttp 124 "GET /usernames HTTP/1.1" 404 2337
WARNING 2018-11-20 22:05:42,068 base 152 Not Found: /usernames/username = 1
WARNING 2018-11-20 22:05:42,068 basehttp 124 "GET /usernames/username%20=%201 HTTP/1.1" 404 2382
WARNING 2018-11-20 22:05:48,029 base 152 Not Found: /usernames
WARNING 2018-11-20 22:05:48,029 basehttp 124 "GET /usernames?username%20=%201 HTTP/1.1" 404 2354
WARNING 2018-11-20 22:05:58,058 base 152 Not Found: /usernames
WARNING 2018-11-20 22:05:58,059 basehttp 124 "GET /usernames?username%20=%201123 HTTP/1.1" 404 2357
WARNING 2018-11-20 22:06:02,811 base 152 Not Found: /usernames
WARNING 2018-11-20 22:06:02,812 basehttp 124 "POST /usernames?username%20=%201123 HTTP/1.1" 404 2358
WARNING 2018-11-20 22:06:08,810 base 152 Not Found: /usernames
WARNING 2018-11-20 22:06:08,811 basehttp 124 "GET /usernames?username%20=%201123 HTTP/1.1" 404 2357
WARNING 2018-11-20 22:44:00,680 base 152 Not Found: /
WARNING 2018-11-20 22:44:00,681 basehttp 124 "GET / HTTP/1.1" 404 2292
WARNING 2018-11-20 22:48:22,603 base 152 Not Found: /users/form
WARNING 2018-11-20 22:48:22,605 basehttp 124 "GET /users/form?a=1&b=2 HTTP/1.1" 404 2352
WARNING 2018-11-20 22:49:35,962 base 152 Not Found: /
WARNING 2018-11-20 22:49:35,963 basehttp 124 "GET / HTTP/1.1" 404 2292
WARNING 2018-11-20 22:50:08,023 base 152 Not Found: /usernames
WARNING 2018-11-20 22:50:08,024 basehttp 124 "GET /usernames HTTP/1.1" 404 2337
WARNING 2018-11-20 22:51:17,063 base 152 Not Found: /usernames
WARNING 2018-11-20 22:51:17,065 basehttp 124 "GET /usernames HTTP/1.1" 404 2346
WARNING 2018-11-20 22:51:37,101 base 152 Not Found: /^ ^usernames/(
WARNING 2018-11-20 22:51:37,102 basehttp 124 "GET /%5E%20%5Eusernames/(?P%3Cusername%3E%5Cw%7B5,20%7D%29/count/$ HTTP/1.1" 404 2408
WARNING 2018-11-20 22:51:42,741 base 152 Not Found: /usernames/(
WARNING 2018-11-20 22:51:42,742 basehttp 124 "GET /usernames/(?P%3Cusername%3E%5Cw%7B5,20%7D%29/count/$ HTTP/1.1" 404 2393
WARNING 2018-11-20 22:52:03,985 base 152 Not Found: /usernames/
WARNING 2018-11-20 22:52:03,987 basehttp 124 "GET /usernames/?username=123/count/ HTTP/1.1" 404 2369
WARNING 2018-11-20 22:52:07,320 base 152 Not Found: /usernames/
WARNING 2018-11-20 22:52:07,320 basehttp 124 "GET /usernames/?username=123 HTTP/1.1" 404 2362
WARNING 2018-11-20 23:02:50,229 base 152 Not Found: /usernames/
WARNING 2018-11-20 23:02:50,230 basehttp 124 "GET /usernames/?username=123 HTTP/1.1" 404 2362
WARNING 2018-11-20 23:28:14,433 base 152 Not Found: /usernames/
WARNING 2018-11-20 23:28:14,436 basehttp 124 "GET /usernames/?username=123 HTTP/1.1" 404 2555
WARNING 2018-11-20 23:37:39,597 base 152 Not Found: /usernames/
WARNING 2018-11-20 23:37:39,600 basehttp 124 "GET /usernames/?username=123/ HTTP/1.1" 404 2556
WARNING 2018-11-20 23:37:55,381 base 152 Not Found: /
WARNING 2018-11-20 23:37:55,382 basehttp 124 "GET / HTTP/1.1" 404 2494
WARNING 2018-11-20 23:38:01,737 base 152 Not Found: /
WARNING 2018-11-20 23:38:01,738 basehttp 124 "GET / HTTP/1.1" 404 2494
WARNING 2018-11-20 23:39:29,210 base 152 Not Found: /usernames/
WARNING 2018-11-20 23:39:29,212 basehttp 124 "GET /usernames/?username=123 HTTP/1.1" 404 84
WARNING 2018-11-20 23:42:40,479 base 152 Not Found: /usernames
WARNING 2018-11-20 23:42:40,481 basehttp 124 "GET /usernames HTTP/1.1" 404 83
WARNING 2018-11-20 23:42:53,693 base 152 Not Found: /
WARNING 2018-11-20 23:42:53,693 basehttp 124 "GET / HTTP/1.1" 404 74
WARNING 2018-11-20 23:43:22,124 base 152 Not Found: /
WARNING 2018-11-20 23:43:22,125 basehttp 124 "GET / HTTP/1.1" 404 74
WARNING 2018-11-20 23:43:28,299 base 152 Not Found: /
WARNING 2018-11-20 23:43:28,300 basehttp 124 "POST / HTTP/1.1" 404 74
WARNING 2018-11-20 23:44:48,932 base 152 Not Found: /usernames/
WARNING 2018-11-20 23:44:48,934 basehttp 124 "GET /usernames/?username=123/ HTTP/1.1" 404 84
WARNING 2018-11-20 23:58:17,860 base 152 Not Found: /usernames/count
WARNING 2018-11-20 23:58:17,862 basehttp 124 "GET /usernames/count HTTP/1.1" 404 2557
WARNING 2018-11-20 23:58:29,144 base 152 Not Found: /usernames/count
WARNING 2018-11-20 23:58:29,145 basehttp 124 "GET /usernames/count HTTP/1.1" 404 2557
INFO 2018-11-20 23:58:51,172 basehttp 124 "GET /usernames/testuser1/count HTTP/1.1" 301 0
INFO 2018-11-20 23:58:51,246 basehttp 124 "GET /usernames/testuser1/count/ HTTP/1.1" 200 34
INFO 2018-11-21 00:01:43,376 basehttp 124 "GET /mobiles/13555555555/count HTTP/1.1" 301 0
ERROR 2018-11-21 00:01:43,401 exception 135 Internal Server Error: /mobiles/13555555555/count/
Traceback (most recent call last):
  File "/Users/zenglihui/.virtualenvs/django_py3_1.0/lib/python3.6/site-packages/django/core/handlers/exception.py", line 41, in inner
    response = get_response(request)
  File "/Users/zenglihui/.virtualenvs/django_py3_1.0/lib/python3.6/site-packages/django/core/handlers/base.py", line 187, in _get_response
    response = self.process_exception_by_middleware(e, request)
  File "/Users/zenglihui/.virtualenvs/django_py3_1.0/lib/python3.6/site-packages/django/core/handlers/base.py", line 185, in _get_response
    response = wrapped_callback(request, *callback_args, **callback_kwargs)
  File "/Users/zenglihui/.virtualenvs/django_py3_1.0/lib/python3.6/site-packages/django/views/decorators/csrf.py", line 58, in wrapped_view
    return view_func(*args, **kwargs)
  File "/Users/zenglihui/.virtualenvs/django_py3_1.0/lib/python3.6/site-packages/django/views/generic/base.py", line 68, in view
    return self.dispatch(request, *args, **kwargs)
  File "/Users/zenglihui/.virtualenvs/django_py3_1.0/lib/python3.6/site-packages/rest_framework/views.py", line 497, in dispatch
    self.response = self.finalize_response(request, response, *args, **kwargs)
  File "/Users/zenglihui/.virtualenvs/django_py3_1.0/lib/python3.6/site-packages/rest_framework/views.py", line 412, in finalize_response
    % type(response)
AssertionError: Expected a `Response`, `HttpResponse` or `HttpStreamingResponse` to be returned from the view, but received a `<class 'type'>`
ERROR 2018-11-21 00:01:43,495 basehttp 124 "GET /mobiles/13555555555/count/ HTTP/1.1" 500 79555
INFO 2018-11-21 00:02:28,321 basehttp 124 "GET /mobiles/13555555555/count HTTP/1.1" 301 0
INFO 2018-11-21 00:02:28,339 basehttp 124 "GET /mobiles/13555555555/count/ HTTP/1.1" 200 34
INFO 2018-11-21 19:19:21,109 basehttp 124 "GET /mobiles/13555555555/count HTTP/1.1" 301 0
INFO 2018-11-21 19:19:21,159 basehttp 124 "GET /mobiles/13555555555/count/ HTTP/1.1" 200 34
WARNING 2018-11-21 19:19:24,372 base 152 Not Found: /
WARNING 2018-11-21 19:19:24,373 basehttp 124 "GET / HTTP/1.1" 404 2649
INFO 2018-11-21 19:20:44,611 basehttp 124 "GET /mobiles/13555555555/count HTTP/1.1" 301 0
INFO 2018-11-21 19:20:44,643 basehttp 124 "GET /mobiles/13555555555/count/ HTTP/1.1" 200 34
WARNING 2018-11-21 19:20:53,251 base 152 Not Found: /
WARNING 2018-11-21 19:20:53,252 basehttp 124 "GET / HTTP/1.1" 404 2649
INFO 2018-11-21 19:21:17,305 basehttp 124 "GET /sms_codes/13555555555 HTTP/1.1" 301 0
ERROR 2018-11-21 19:21:17,312 exception 135 Internal Server Error: /sms_codes/13555555555/
Traceback (most recent call last):
  File "/Users/zenglihui/.virtualenvs/django_py3_1.0/lib/python3.6/site-packages/django/core/handlers/exception.py", line 41, in inner
    response = get_response(request)
  File "/Users/zenglihui/.virtualenvs/django_py3_1.0/lib/python3.6/site-packages/django/core/handlers/base.py", line 187, in _get_response
    response = self.process_exception_by_middleware(e, request)
  File "/Users/zenglihui/.virtualenvs/django_py3_1.0/lib/python3.6/site-packages/django/core/handlers/base.py", line 185, in _get_response
    response = wrapped_callback(request, *callback_args, **callback_kwargs)
  File "/Users/zenglihui/.virtualenvs/django_py3_1.0/lib/python3.6/site-packages/django/views/decorators/csrf.py", line 58, in wrapped_view
    return view_func(*args, **kwargs)
  File "/Users/zenglihui/.virtualenvs/django_py3_1.0/lib/python3.6/site-packages/django/views/generic/base.py", line 68, in view
    return self.dispatch(request, *args, **kwargs)
  File "/Users/zenglihui/.virtualenvs/django_py3_1.0/lib/python3.6/site-packages/rest_framework/views.py", line 495, in dispatch
    response = self.handle_exception(exc)
  File "/Users/zenglihui/.virtualenvs/django_py3_1.0/lib/python3.6/site-packages/rest_framework/views.py", line 455, in handle_exception
    self.raise_uncaught_exception(exc)
  File "/Users/zenglihui/.virtualenvs/django_py3_1.0/lib/python3.6/site-packages/rest_framework/views.py", line 492, in dispatch
    response = handler(request, *args, **kwargs)
  File "/Users/zenglihui/PycharmProjects/meiduo_mall/meiduo_mall/meiduo_mall/apps/verifications/views.py", line 24, in get
    redis_conn = get_redis_connection("verifications")
  File "/Users/zenglihui/.virtualenvs/django_py3_1.0/lib/python3.6/site-packages/django_redis/__init__.py", line 14, in get_redis_connection
    cache = caches[alias]
  File "/Users/zenglihui/.virtualenvs/django_py3_1.0/lib/python3.6/site-packages/django/core/cache/__init__.py", line 77, in __getitem__
    "Could not find config for '%s' in settings.CACHES" % alias
django.core.cache.backends.base.InvalidCacheBackendError: Could not find config for 'verifications' in settings.CACHES
ERROR 2018-11-21 19:21:17,369 basehttp 124 "GET /sms_codes/13555555555/ HTTP/1.1" 500 16439
INFO 2018-11-21 19:42:36,248 basehttp 124 "GET /sms_codes/13555555555 HTTP/1.1" 301 0
ERROR 2018-11-21 19:42:36,285 exception 135 Internal Server Error: /sms_codes/13555555555/
Traceback (most recent call last):
  File "/Users/zenglihui/.virtualenvs/django_py3_1.0/lib/python3.6/site-packages/django/core/handlers/exception.py", line 41, in inner
    response = get_response(request)
  File "/Users/zenglihui/.virtualenvs/django_py3_1.0/lib/python3.6/site-packages/django/core/handlers/base.py", line 187, in _get_response
    response = self.process_exception_by_middleware(e, request)
  File "/Users/zenglihui/.virtualenvs/django_py3_1.0/lib/python3.6/site-packages/django/core/handlers/base.py", line 185, in _get_response
    response = wrapped_callback(request, *callback_args, **callback_kwargs)
  File "/Users/zenglihui/.virtualenvs/django_py3_1.0/lib/python3.6/site-packages/django/views/decorators/csrf.py", line 58, in wrapped_view
    return view_func(*args, **kwargs)
  File "/Users/zenglihui/.virtualenvs/django_py3_1.0/lib/python3.6/site-packages/django/views/generic/base.py", line 68, in view
    return self.dispatch(request, *args, **kwargs)
  File "/Users/zenglihui/.virtualenvs/django_py3_1.0/lib/python3.6/site-packages/rest_framework/views.py", line 495, in dispatch
    response = self.handle_exception(exc)
  File "/Users/zenglihui/.virtualenvs/django_py3_1.0/lib/python3.6/site-packages/rest_framework/views.py", line 455, in handle_exception
    self.raise_uncaught_exception(exc)
  File "/Users/zenglihui/.virtualenvs/django_py3_1.0/lib/python3.6/site-packages/rest_framework/views.py", line 492, in dispatch
    response = handler(request, *args, **kwargs)
  File "/Users/zenglihui/PycharmProjects/meiduo_mall/meiduo_mall/meiduo_mall/apps/verifications/views.py", line 37, in get
    pl = redis_conn.pipline()
AttributeError: 'StrictRedis' object has no attribute 'pipline'
ERROR 2018-11-21 19:42:36,351 basehttp 124 "GET /sms_codes/13555555555/ HTTP/1.1" 500 16168
INFO 2018-11-21 19:46:53,740 basehttp 124 "GET /sms_codes/13555555555 HTTP/1.1" 301 0
ERROR 2018-11-21 19:46:53,761 exception 135 Internal Server Error: /sms_codes/13555555555/
Traceback (most recent call last):
  File "/Users/zenglihui/.virtualenvs/django_py3_1.0/lib/python3.6/site-packages/django/core/handlers/exception.py", line 41, in inner
    response = get_response(request)
  File "/Users/zenglihui/.virtualenvs/django_py3_1.0/lib/python3.6/site-packages/django/core/handlers/base.py", line 187, in _get_response
    response = self.process_exception_by_middleware(e, request)
  File "/Users/zenglihui/.virtualenvs/django_py3_1.0/lib/python3.6/site-packages/django/core/handlers/base.py", line 185, in _get_response
    response = wrapped_callback(request, *callback_args, **callback_kwargs)
  File "/Users/zenglihui/.virtualenvs/django_py3_1.0/lib/python3.6/site-packages/django/views/decorators/csrf.py", line 58, in wrapped_view
    return view_func(*args, **kwargs)
  File "/Users/zenglihui/.virtualenvs/django_py3_1.0/lib/python3.6/site-packages/django/views/generic/base.py", line 68, in view
    return self.dispatch(request, *args, **kwargs)
  File "/Users/zenglihui/.virtualenvs/django_py3_1.0/lib/python3.6/site-packages/rest_framework/views.py", line 495, in dispatch
    response = self.handle_exception(exc)
  File "/Users/zenglihui/.virtualenvs/django_py3_1.0/lib/python3.6/site-packages/rest_framework/views.py", line 455, in handle_exception
    self.raise_uncaught_exception(exc)
  File "/Users/zenglihui/.virtualenvs/django_py3_1.0/lib/python3.6/site-packages/rest_framework/views.py", line 492, in dispatch
    response = handler(request, *args, **kwargs)
  File "/Users/zenglihui/PycharmProjects/meiduo_mall/meiduo_mall/meiduo_mall/apps/verifications/views.py", line 47, in get
    sms_code_expires = constants.SMS_CODE_REDIS_EXPIRE // 60
NameError: name 'constants' is not defined
ERROR 2018-11-21 19:46:53,817 basehttp 124 "GET /sms_codes/13555555555/ HTTP/1.1" 500 16157
INFO 2018-11-21 19:48:28,756 basehttp 124 "GET /sms_codes/13555555555 HTTP/1.1" 301 0
ERROR 2018-11-21 19:48:28,773 basehttp 124 "GET /sms_codes/13555555555/ HTTP/1.1" 507 33
INFO 2018-11-21 20:51:58,766 basehttp 124 "GET /sms_codes/13555555555 HTTP/1.1" 301 0
ERROR 2018-11-21 20:51:58,802 exception 135 Internal Server Error: /sms_codes/13555555555/
Traceback (most recent call last):
  File "/Users/zenglihui/.virtualenvs/django_py3_1.0/lib/python3.6/site-packages/django/core/handlers/exception.py", line 41, in inner
    response = get_response(request)
  File "/Users/zenglihui/.virtualenvs/django_py3_1.0/lib/python3.6/site-packages/django/core/handlers/base.py", line 187, in _get_response
    response = self.process_exception_by_middleware(e, request)
  File "/Users/zenglihui/.virtualenvs/django_py3_1.0/lib/python3.6/site-packages/django/core/handlers/base.py", line 185, in _get_response
    response = wrapped_callback(request, *callback_args, **callback_kwargs)
  File "/Users/zenglihui/.virtualenvs/django_py3_1.0/lib/python3.6/site-packages/django/views/decorators/csrf.py", line 58, in wrapped_view
    return view_func(*args, **kwargs)
  File "/Users/zenglihui/.virtualenvs/django_py3_1.0/lib/python3.6/site-packages/django/views/generic/base.py", line 68, in view
    return self.dispatch(request, *args, **kwargs)
  File "/Users/zenglihui/.virtualenvs/django_py3_1.0/lib/python3.6/site-packages/rest_framework/views.py", line 495, in dispatch
    response = self.handle_exception(exc)
  File "/Users/zenglihui/.virtualenvs/django_py3_1.0/lib/python3.6/site-packages/rest_framework/views.py", line 455, in handle_exception
    self.raise_uncaught_exception(exc)
  File "/Users/zenglihui/.virtualenvs/django_py3_1.0/lib/python3.6/site-packages/rest_framework/views.py", line 492, in dispatch
    response = handler(request, *args, **kwargs)
  File "/Users/zenglihui/PycharmProjects/meiduo_mall/meiduo_mall/meiduo_mall/apps/verifications/views.py", line 50, in get
    sms_tasks.delay(mobile, sms_code, 5)
AttributeError: module 'celery_tasks.sms.tasks' has no attribute 'delay'
ERROR 2018-11-21 20:51:58,960 basehttp 124 "GET /sms_codes/13555555555/ HTTP/1.1" 500 16196
INFO 2018-11-21 20:56:20,641 basehttp 124 "GET /sms_codes/13555555555 HTTP/1.1" 301 0
INFO 2018-11-21 20:56:20,731 basehttp 124 "GET /sms_codes/13555555555/ HTTP/1.1" 200 16
INFO 2018-11-21 20:58:12,932 basehttp 124 "GET /sms_codes/13555555555 HTTP/1.1" 301 0
INFO 2018-11-21 20:58:12,943 basehttp 124 "GET /sms_codes/13555555555/ HTTP/1.1" 200 16
INFO 2018-11-21 20:58:15,155 basehttp 124 "GET /sms_codes/13555555555 HTTP/1.1" 301 0
INFO 2018-11-21 20:58:15,160 basehttp 124 "GET /sms_codes/13555555555/ HTTP/1.1" 200 16
INFO 2018-11-21 20:58:15,867 basehttp 124 "GET /sms_codes/13555555555 HTTP/1.1" 301 0
INFO 2018-11-21 20:58:15,882 basehttp 124 "GET /sms_codes/13555555555/ HTTP/1.1" 200 16
INFO 2018-11-21 20:58:16,342 basehttp 124 "GET /sms_codes/13555555555 HTTP/1.1" 301 0
INFO 2018-11-21 20:58:16,349 basehttp 124 "GET /sms_codes/13555555555/ HTTP/1.1" 200 16
INFO 2018-11-21 20:58:16,651 basehttp 124 "GET /sms_codes/13555555555 HTTP/1.1" 301 0
INFO 2018-11-21 20:58:16,659 basehttp 124 "GET /sms_codes/13555555555/ HTTP/1.1" 200 16
INFO 2018-11-21 20:58:17,333 basehttp 124 "GET /sms_codes/13555555555 HTTP/1.1" 301 0
INFO 2018-11-21 20:58:17,344 basehttp 124 "GET /sms_codes/13555555555/ HTTP/1.1" 200 16
INFO 2018-11-21 20:58:17,618 basehttp 124 "GET /sms_codes/13555555555 HTTP/1.1" 301 0
INFO 2018-11-21 20:58:17,623 basehttp 124 "GET /sms_codes/13555555555/ HTTP/1.1" 200 16
INFO 2018-11-21 20:58:22,455 basehttp 124 "GET /sms_codes/13555555557 HTTP/1.1" 301 0
INFO 2018-11-21 20:58:22,460 basehttp 124 "GET /sms_codes/13555555557/ HTTP/1.1" 200 16
INFO 2018-11-21 21:00:07,327 basehttp 124 "GET /sms_codes/13555555559 HTTP/1.1" 301 0
INFO 2018-11-21 21:00:07,412 basehttp 124 "GET /sms_codes/13555555559/ HTTP/1.1" 200 16
INFO 2018-11-21 21:01:07,221 basehttp 124 "GET /sms_codes/13555555559 HTTP/1.1" 301 0
INFO 2018-11-21 21:01:07,290 basehttp 124 "GET /sms_codes/13555555559/ HTTP/1.1" 200 16
ERROR 2018-11-21 21:18:32,295 tasks 25  发送验证码短信[异常] [mobile: 13555555555, message: name 'ccp' is not defined]
ERROR 2018-11-21 21:18:32,298 tasks 25  发送验证码短信[异常] [mobile: 13555555555, message: name 'ccp' is not defined]
ERROR 2018-11-21 21:18:32,300 tasks 25  发送验证码短信[异常] [mobile: 13555555555, message: name 'ccp' is not defined]
ERROR 2018-11-21 21:18:32,303 tasks 25  发送验证码短信[异常] [mobile: 13555555555, message: name 'ccp' is not defined]
ERROR 2018-11-21 21:18:32,306 tasks 25  发送验证码短信[异常] [mobile: 13555555555, message: name 'ccp' is not defined]
ERROR 2018-11-21 21:18:32,309 tasks 25  发送验证码短信[异常] [mobile: 13555555555, message: name 'ccp' is not defined]
ERROR 2018-11-21 21:18:32,309 tasks 25  发送验证码短信[异常] [mobile: 13555555555, message: name 'ccp' is not defined]
ERROR 2018-11-21 21:18:32,315 tasks 25  发送验证码短信[异常] [mobile: 13555555555, message: name 'ccp' is not defined]
ERROR 2018-11-21 21:18:32,315 tasks 25  发送验证码短信[异常] [mobile: 13555555557, message: name 'ccp' is not defined]
ERROR 2018-11-21 21:18:32,320 tasks 25  发送验证码短信[异常] [mobile: 13555555559, message: name 'ccp' is not defined]
ERROR 2018-11-21 21:18:32,322 tasks 25  发送验证码短信[异常] [mobile: 13555555559, message: name 'ccp' is not defined]
INFO 2018-11-21 21:20:31,056 basehttp 124 "GET /sms_codes/13555555558 HTTP/1.1" 301 0
INFO 2018-11-21 21:20:31,098 basehttp 124 "GET /sms_codes/13555555558/ HTTP/1.1" 200 16
ERROR 2018-11-21 21:20:31,103 tasks 25  发送验证码短信[异常] [mobile: 13555555558, message: name 'ccp' is not defined]
INFO 2018-11-21 21:21:21,193 basehttp 124 "GET /sms_codes/13555555558 HTTP/1.1" 301 0
INFO 2018-11-21 21:21:21,257 basehttp 124 "GET /sms_codes/13555555558/ HTTP/1.1" 200 16
WARNING 2018-11-21 21:21:21,377 tasks 31 发送验证码短信[失败] [ mobile: 13555555558 ]
